Workbook

Sheet 1Tarifas Distribuidoras - INPUT
A1: Dados Distribuidora | M1: PONTA | R1: FORA PONTA | W1: ENCARGO
A2: Distribuidora | B2: Início de Vigência | C2: Fim de Vigência | D2: USO DA REDE PONTA | E2: USO DA REDE F. PONTA | F2: ENCARGO | G2: Encargo Auto Produtor | H2: Desconto Auto-Produção | I2: ICMS | J2: PIS | K2: COFINS | L2: PIS/COFINS Faturamento Distribuidora | M2: Valor Bruto Ponta | N2: Valor ICMS | O2: Valor PIS Ponta | P2: Valor COFINS Ponta | Q2: LIQUIDO SAP | R2: Valor Bruto Ponta | S2: Valor ICMS | T2: Valor PIS Ponta | U2: Valor COFINS Ponta | V2: LIQUIDO SAP | W2: Valor Bruto Ponta | X2: Valor ICMS | Y2: Valor PIS Ponta | Z2: Valor COFINS Ponta | AA2: LIQUIDO SAP
A3: ONS | B3: 45839 | C3: 46203 | D3: 7.099 | E3: 7.086 | F3: 66.52 | G3: 0 | H3: =F3-G3 -> 66.52 | I3: 0.18 | J3: 0.0165 | K3: 0.076 | L3: 0.08 | M3: =($D3/(1-$I3))/(1-$L3) -> 9.4101273 | N3: =M3*$I$3 -> 1.6938229 | O3: =M3*$J$3 -> 0.1552671 | P3: =M3*$K$3 -> 0.71516967 | Q3: =M3-O3-P3-N3 -> 6.8458676 | R3: =($E3/(1-$I3))/(1-$L3) -> 9.392895 | S3: =R3*$I3 -> 1.6907211 | T3: =R3*$J3 -> 0.15498277 | U3: =R3*$K3 -> 0.71386002 | V3: =R3-T3-U3-S3 -> 6.8333311 | W3: =($F3/(1-$I3))/(1-$L3) -> 88.176034 | X3: =W3*$I3 -> 15.871686 | Y3: =W3*$J3 -> 1.4549046 | Z3: =W3*$K3 -> 6.7013786 | AA3: =W3-Y3-Z3-X3 -> 64.148065
A4: ONS | B4: 46204 | C4: 46568 | D4: 7.78 | E4: 7.82 | F4: 60.66 | G4: 0 | H4: =F4-G4 -> 60.66 | I4: 0.18 | J4: 0.0165 | K4: 0.076 | L4: 0.08 | M4: =($D4/(1-I4))/(1-L4) -> 10.312831 | N4: =M4*I4 -> 1.8563097 | O4: =M4*J4 -> 0.17016172 | P4: =M4*K4 -> 0.78377519 | Q4: =M4-O4-P4-N4 -> 7.5025848 | R4: =($E4/(1-$I4))/(1-$L4) -> 10.365854 | S4: =R4*$I4 -> 1.8658537 | T4: =R4*$J4 -> 0.17103659 | U4: =R4*$K4 -> 0.78780488 | V4: =R4-T4-U4-S4 -> 7.5411585 | W4: =($F4/(1-$I4))/(1-$L4) -> 80.408271 | X4: =W4*$I4 -> 14.473489 | Y4: =W4*$J4 -> 1.3267365 | Z4: =W4*$K4 -> 6.1110286 | AA4: =W4-Y4-Z4-X4 -> 58.497017
A5: EDP | B5: 45870 | C5: 46234 | D5: 21.44 | E5: 9.83 | F5: 90.88 | G5: 13.33 | H5: =F5-G5 -> 77.55 | I5: 0.17 | J5: 0.0165 | K5: 0.076 | L5: 0.07 | M5: =($D5/(1-I5))/(1-L5) -> 27.775619 | N5: =M5*I5 -> 4.7218552 | O5: =M5*J5 -> 0.45829771 | P5: =M5*K5 -> 2.110947 | Q5: =M5-O5-P5-N5 -> 20.484519 | R5: =($E5/(1-$I5))/(1-$L5) -> 12.73481 | S5: =R5*$I5 -> 2.1649177 | T5: =R5*$J5 -> 0.21012437 | U5: =R5*$K5 -> 0.96784558 | V5: =R5-T5-U5-S5 -> 9.3919225 | W5: =($F5/(1-$I5))/(1-$L5) -> 117.73546 | X5: =W5*$I5 -> 20.015028 | Y5: =W5*$J5 -> 1.9426351 | Z5: =W5*$K5 -> 8.9478948 | AA5: =W5-Y5-Z5-X5 -> 86.8299
A6: EDP | B6: 46235 | C6: 46599 | D6: 21.056063 | E6: 8.941315 | F6: 87.09764 | G6: 8.4769741 | H6: =F6-G6 -> 78.620665 | I6: 0.17 | J6: 0.0165 | K6: 0.076 | L6: 0.07 | M6: =($D6/(1-I6))/(1-L6) -> 27.278227 | N6: =M6*I6 -> 4.6372985 | O6: =M6*J6 -> 0.45009074 | P6: =M6*K6 -> 2.0731452 | Q6: =M6-O6-P6-N6 -> 20.117692 | R6: =($E6/(1-$I6))/(1-$L6) -> 11.583515 | S6: =R6*$I6 -> 1.9691975 | T6: =R6*$J6 -> 0.19112799 | U6: =R6*$K6 -> 0.88034712 | V6: =R6-T6-U6-S6 -> 8.5428421 | W6: =($F6/(1-$I6))/(1-$L6) -> 112.83539 | X6: =W6*$I6 -> 19.182017 | Y6: =W6*$J6 -> 1.861784 | Z6: =W6*$K6 -> 8.5754898 | AA6: =W6-Y6-Z6-X6 -> 83.216102
A7: ENERGISA | B7: 45839 | C7: 46203 | D7: 15.96 | E7: 8.58 | F7: 83.19 | G7: 12.754801 | H7: =F7-G7 -> 70.435199 | I7: 0 | J7: 0.0165 | K7: 0.076 | L7: 0.07 | M7: =($D7/(1-I7))/(1-L7) -> 17.16129 | N7: =M7*I7 -> 0 | O7: =M7*J7 -> 0.28316129 | P7: =M7*K7 -> 1.3042581 | Q7: =M7-O7-P7-N7 -> 15.573871 | R7: =($E7/(1-$I7))/(1-$L7) -> 9.2258065 | S7: =R7*$I7 -> 0 | T7: =R7*$J7 -> 0.15222581 | U7: =R7*$K7 -> 0.70116129 | V7: =R7-T7-U7-S7 -> 8.3724194 | W7: =($F7/(1-$I7))/(1-$L7) -> 89.451613 | X7: =W7*$I7 -> 0 | Y7: =W7*$J7 -> 1.4759516 | Z7: =W7*$K7 -> 6.7983226 | AA7: =W7-Y7-Z7-X7 -> 81.177339
A8: ENERGISA | B8: 46204 | C8: 46568 | D8: 29.665248 | E8: 11.691942 | F8: 84.428166 | G8: 9.9877642 | H8: =F8-G8 -> 74.440402 | I8: 0 | J8: 0.0165 | K8: 0.076 | L8: 0.07 | M8: =($D8/(1-I8))/(1-L8) -> 31.898117 | N8: =M8*I8 -> 0 | O8: =M8*J8 -> 0.52631892 | P8: =M8*K8 -> 2.4242569 | Q8: =M8-O8-P8-N8 -> 28.947541 | R8: =($E8/(1-$I8))/(1-$L8) -> 12.571981 | S8: =R8*$I8 -> 0 | T8: =R8*$J8 -> 0.20743768 | U8: =R8*$K8 -> 0.95547052 | V8: =R8-T8-U8-S8 -> 11.409072 | W8: =($F8/(1-$I8))/(1-$L8) -> 90.782975 | X8: =W8*$I8 -> 0 | Y8: =W8*$J8 -> 1.4979191 | Z8: =W8*$K8 -> 6.8995061 | AA8: =W8-Y8-Z8-X8 -> 82.385549
M9: CALCULO
A10: Fornecedores de Energia - Mercado Livre
A11: Fornecedor | B11: Data Base | C11: Preço Base | D11: IPCA Realizado | E11: IPCA Projetado | F11: IPCA Total | G11: Preço | H11: Montante | I11: Valor Montante
A12: Cemig Convencional | B12: 44317 | C12: 142.59 | D12: 0.276 | E12: 0.0235 | F12: =D12+E12 -> 0.2995 | G12: =(C12)+(C12*F12) -> 185.2957 | H12: 80 | I12: =H12*G12 -> 14823.656
A13: Cemig Incentivada | B13: 45231 | C13: 152.88 | D13: 0.0874 | E13: 0.0199 | F13: =D13+E13 -> 0.1073 | G13: =(C13)+(C13*F13) -> 169.28402 | H13: 10 | I13: =H13*G13 -> 1692.8402
A14: Elera | B14: 45323 | C14: 159.2 | D14: 0.0679 | E14: 0.0196 | F14: =D14+E14 -> 0.0875 | G14: =(C14)+(C14*F14) -> 173.13 | H14: 20 | I14: =H14*G14 -> 3462.6
A15: Matrix | B15: 45383 | C15: 143.4 | D15: 0.0622 | E15: 0.0195 | F15: =D15+E15 -> 0.0817 | G15: =(C15)+(C15*F15) -> 155.11578 | H15: 20 | I15: =H15*G15 -> 3102.3156
I16: =SUM(I12:I15)/SUM(H12:H15) -> 177.54932
A18: Considerar que hdaverá um campo para cadastrar o valor do iPCA do mês de faturamento até o final do ano corrente, para projetar o custo do ano seguinte
A20: CALCULO
A21: Valor de Energia Por Estado | C21: ICMS | D21: PIS | E21: COFINS | F21: IPCA | G21: Valor Bruto | H21: Valor ICMS | I21: Valor PIS | J21: Valor Cofins | K21: LIQUIDO SAP
A22: MG | B22: =$I$16 -> 177.54932 | C22: 0.18 | D22: 0.0165 | E22: 0.076 | F22: 0.0216 | G22: =(B22/(1-F22))/(1-C22) -> 221.30373 | H22: =G22*C22 -> 39.834671 | I22: =G22*D22 -> 3.6515115 | J22: =G22*E22 -> 16.819083 | K22: =G22-I22-J22-H22 -> 160.99846
A23: ES | B23: =$I$16 -> 177.54932 | C23: 0.17 | D23: 0.0165 | E23: 0.076 | F23: 0.0216 | G23: =(B23/(1-F23))/(1-C23) -> 218.63742 | H23: =G23*C23 -> 37.168361 | I23: =G23*D23 -> 3.6075174 | J23: =G23*E23 -> 16.616444 | K23: =G23-I23-J23-H23 -> 161.2451
A25: Deverá haver cadastro de estados, informando para cada ano, o valor dos impostos de PIS/COFINS e ICMS. Deverá haver cadastro de unidades, e todas as unidades deverão ser cadastradas, incluvise as que geram energia. No cadastro de unidades, deverá indicar se é uma idade de produção de energia ou não. Quando não for uma unidade de produção de energia, deverá indicar se irá receber créditos de geração de energia, e deverá escolher sobre qual unidade receberá esses créditos. No cadastro de unidade, tambem deverá haver indicação se ela está conectada na rede de distribuição ou na rede basica

Sheet 2Tabela Tarifas Distribuidoras
A1: MG | E1: Janeiro Pjanejado | F1: Fevereiro Pjanejado | G1: Março Pjanejado | H1: Abril Pjanejado | I1: Maio Pjanejado | J1: Junho Pjanejado | K1: Julho Pjanejado | L1: Agosto Pjanejado | M1: Setembro Pjanejado | N1: Outubro Pjanejado | O1: Novembro Pjanejado | P1: Dezembro Pjanejado
A2: Unidade | B2: Serviço | C2: Horário/Encargo | D2: Centro de Custo
A3: Germano | B3: TUSD FIO / DEMANDA | C3: Ponta | D3: 50610003 | E3: ='1Tarifas Distribuidoras - INPUT'!$Q$3 -> 6.8458676 | F3: ='1Tarifas Distribuidoras - INPUT'!$Q$3 -> 6.8458676 | G3: ='1Tarifas Distribuidoras - INPUT'!$Q$3 -> 6.8458676 | H3: ='1Tarifas Distribuidoras - INPUT'!$Q$3 -> 6.8458676 | I3: ='1Tarifas Distribuidoras - INPUT'!$Q$3 -> 6.8458676 | J3: ='1Tarifas Distribuidoras - INPUT'!$Q$3 -> 6.8458676 | K3: ='1Tarifas Distribuidoras - INPUT'!$Q$4 -> 7.5025848 | L3: ='1Tarifas Distribuidoras - INPUT'!$Q$4 -> 7.5025848 | M3: ='1Tarifas Distribuidoras - INPUT'!$Q$4 -> 7.5025848 | N3: ='1Tarifas Distribuidoras - INPUT'!$Q$4 -> 7.5025848 | O3: ='1Tarifas Distribuidoras - INPUT'!$Q$4 -> 7.5025848 | P3: ='1Tarifas Distribuidoras - INPUT'!$Q$4 -> 7.5025848
A4: Germano | B4: TUSD FIO / DEMANDA | C4: Fora Ponta | D4: 50610003 | E4: ='1Tarifas Distribuidoras - INPUT'!$V$3 -> 6.8333311 | F4: ='1Tarifas Distribuidoras - INPUT'!$V$3 -> 6.8333311 | G4: ='1Tarifas Distribuidoras - INPUT'!$V$3 -> 6.8333311 | H4: ='1Tarifas Distribuidoras - INPUT'!$V$3 -> 6.8333311 | I4: ='1Tarifas Distribuidoras - INPUT'!$V$3 -> 6.8333311 | J4: ='1Tarifas Distribuidoras - INPUT'!$V$3 -> 6.8333311 | K4: ='1Tarifas Distribuidoras - INPUT'!$V$4 -> 7.5411585 | L4: ='1Tarifas Distribuidoras - INPUT'!$V$4 -> 7.5411585 | M4: ='1Tarifas Distribuidoras - INPUT'!$V$4 -> 7.5411585 | N4: ='1Tarifas Distribuidoras - INPUT'!$V$4 -> 7.5411585 | O4: ='1Tarifas Distribuidoras - INPUT'!$V$4 -> 7.5411585 | P4: ='1Tarifas Distribuidoras - INPUT'!$V$4 -> 7.5411585
A5: Germano | B5: TUSD ENCARGO | C5: Encargo Transmis | D5: 50610006 | E5: ='1Tarifas Distribuidoras - INPUT'!$AA$3 -> 64.148065 | F5: ='1Tarifas Distribuidoras - INPUT'!$AA$3 -> 64.148065 | G5: ='1Tarifas Distribuidoras - INPUT'!$AA$3 -> 64.148065 | H5: ='1Tarifas Distribuidoras - INPUT'!$AA$3 -> 64.148065 | I5: ='1Tarifas Distribuidoras - INPUT'!$AA$3 -> 64.148065 | J5: ='1Tarifas Distribuidoras - INPUT'!$AA$4 -> 58.497017 | K5: ='1Tarifas Distribuidoras - INPUT'!$AA$4 -> 58.497017 | L5: ='1Tarifas Distribuidoras - INPUT'!$AA$4 -> 58.497017 | M5: ='1Tarifas Distribuidoras - INPUT'!$AA$4 -> 58.497017 | N5: ='1Tarifas Distribuidoras - INPUT'!$AA$4 -> 58.497017 | O5: ='1Tarifas Distribuidoras - INPUT'!$AA$4 -> 58.497017 | P5: ='1Tarifas Distribuidoras - INPUT'!$AA$4 -> 58.497017
A6: Germano | B6: TUSD ENCARGO | C6: Desconto Enc. G.A. | D6: 50610006 | E6: ='1Tarifas Distribuidoras - INPUT'!$H$3 -> 66.52 | F6: ='1Tarifas Distribuidoras - INPUT'!$H$3 -> 66.52 | G6: ='1Tarifas Distribuidoras - INPUT'!$H$3 -> 66.52 | H6: ='1Tarifas Distribuidoras - INPUT'!$H$3 -> 66.52 | I6: ='1Tarifas Distribuidoras - INPUT'!$H$3 -> 66.52 | J6: ='1Tarifas Distribuidoras - INPUT'!$H$3 -> 66.52 | K6: ='1Tarifas Distribuidoras - INPUT'!$H$4 -> 60.66 | L6: ='1Tarifas Distribuidoras - INPUT'!$H$4 -> 60.66 | M6: ='1Tarifas Distribuidoras - INPUT'!$H$4 -> 60.66 | N6: ='1Tarifas Distribuidoras - INPUT'!$H$4 -> 60.66 | O6: ='1Tarifas Distribuidoras - INPUT'!$H$4 -> 60.66 | P6: ='1Tarifas Distribuidoras - INPUT'!$H$4 -> 60.66
A7: Germano | B7: TUSD ENCARGO | C7: Encargo Distribuição | D7: 50610006
A8: Matipó | B8: TUSD FIO / DEMANDA | C8: Ponta | D8: 50610003 | E8: ='1Tarifas Distribuidoras - INPUT'!$Q$7 -> 15.573871 | F8: ='1Tarifas Distribuidoras - INPUT'!$Q$7 -> 15.573871 | G8: ='1Tarifas Distribuidoras - INPUT'!$Q$7 -> 15.573871 | H8: ='1Tarifas Distribuidoras - INPUT'!$Q$7 -> 15.573871 | I8: ='1Tarifas Distribuidoras - INPUT'!$Q$7 -> 15.573871 | J8: ='1Tarifas Distribuidoras - INPUT'!$Q$7 -> 15.573871 | K8: ='1Tarifas Distribuidoras - INPUT'!$D$8 -> 29.665248 | L8: ='1Tarifas Distribuidoras - INPUT'!$D$8 -> 29.665248 | M8: ='1Tarifas Distribuidoras - INPUT'!$D$8 -> 29.665248 | N8: ='1Tarifas Distribuidoras - INPUT'!$D$8 -> 29.665248 | O8: ='1Tarifas Distribuidoras - INPUT'!$D$8 -> 29.665248 | P8: ='1Tarifas Distribuidoras - INPUT'!$D$8 -> 29.665248
A9: Matipó | B9: TUSD FIO / DEMANDA | C9: Fora Ponta | D9: 50610003 | E9: ='1Tarifas Distribuidoras - INPUT'!$V$7 -> 8.3724194 | F9: ='1Tarifas Distribuidoras - INPUT'!$V$7 -> 8.3724194 | G9: ='1Tarifas Distribuidoras - INPUT'!$V$7 -> 8.3724194 | H9: ='1Tarifas Distribuidoras - INPUT'!$V$7 -> 8.3724194 | I9: ='1Tarifas Distribuidoras - INPUT'!$V$7 -> 8.3724194 | J9: ='1Tarifas Distribuidoras - INPUT'!$V$7 -> 8.3724194 | K9: ='1Tarifas Distribuidoras - INPUT'!$E$8 -> 11.691942 | L9: ='1Tarifas Distribuidoras - INPUT'!$E$8 -> 11.691942 | M9: ='1Tarifas Distribuidoras - INPUT'!$E$8 -> 11.691942 | N9: ='1Tarifas Distribuidoras - INPUT'!$E$8 -> 11.691942 | O9: ='1Tarifas Distribuidoras - INPUT'!$E$8 -> 11.691942 | P9: ='1Tarifas Distribuidoras - INPUT'!$E$8 -> 11.691942
A10: Matipó | B10: TUSD ENCARGO | C10: Encargo Transmis | D10: 50610006
A11: Matipó | B11: TUSD ENCARGO | C11: Desconto Enc. G.A. | D11: 50610006
A12: Matipó | B12: TUSD ENCARGO | C12: Encargo Distribuição | D12: 50610006 | E12: ='1Tarifas Distribuidoras - INPUT'!$AA$7 -> 81.177339 | F12: ='1Tarifas Distribuidoras - INPUT'!$AA$7 -> 81.177339 | G12: ='1Tarifas Distribuidoras - INPUT'!$AA$7 -> 81.177339 | H12: ='1Tarifas Distribuidoras - INPUT'!$AA$7 -> 81.177339 | I12: ='1Tarifas Distribuidoras - INPUT'!$AA$7 -> 81.177339 | J12: ='1Tarifas Distribuidoras - INPUT'!$AA$7 -> 81.177339 | K12: ='1Tarifas Distribuidoras - INPUT'!$AA$8 -> 82.385549 | L12: ='1Tarifas Distribuidoras - INPUT'!$AA$8 -> 82.385549 | M12: ='1Tarifas Distribuidoras - INPUT'!$AA$8 -> 82.385549 | N12: ='1Tarifas Distribuidoras - INPUT'!$AA$8 -> 82.385549 | O12: ='1Tarifas Distribuidoras - INPUT'!$AA$8 -> 82.385549 | P12: ='1Tarifas Distribuidoras - INPUT'!$AA$8 -> 82.385549
A13: MG | B13: Consumo de Energia | C13: PMIX | D13: 50610002 | E13: ='1Tarifas Distribuidoras - INPUT'!$K$22 -> 160.99846 | F13: ='1Tarifas Distribuidoras - INPUT'!$K$22 -> 160.99846 | G13: ='1Tarifas Distribuidoras - INPUT'!$K$22 -> 160.99846 | H13: ='1Tarifas Distribuidoras - INPUT'!$K$22 -> 160.99846 | I13: ='1Tarifas Distribuidoras - INPUT'!$K$22 -> 160.99846 | J13: ='1Tarifas Distribuidoras - INPUT'!$K$22 -> 160.99846 | K13: ='1Tarifas Distribuidoras - INPUT'!$K$22 -> 160.99846 | L13: ='1Tarifas Distribuidoras - INPUT'!$K$22 -> 160.99846 | ... P13: ='1Tarifas Distribuidoras - INPUT'!$K$22 -> 160.99846
A15: ES | E15: Janeiro Pjanejado | F15: Fevereiro Pjanejado | G15: Março Pjanejado | H15: Abril Pjanejado | I15: Maio Pjanejado | J15: Junho Pjanejado | K15: Julho Pjanejado | L15: Agosto Pjanejado | M15: Setembro Pjanejado | N15: Outubro Pjanejado | O15: Novembro Pjanejado | P15: Dezembro Pjanejado
A16: Unidade | B16: Serviço | C16: Horário/Encargo | D16: Centro de Custo
A17: UBU | B17: TUSD FIO / DEMANDA | C17: Ponta | D17: 50610003 | E17: ='1Tarifas Distribuidoras - INPUT'!$Q$5 -> 20.484519 | F17: ='1Tarifas Distribuidoras - INPUT'!$Q$5 -> 20.484519 | G17: ='1Tarifas Distribuidoras - INPUT'!$Q$5 -> 20.484519 | H17: ='1Tarifas Distribuidoras - INPUT'!$Q$5 -> 20.484519 | I17: ='1Tarifas Distribuidoras - INPUT'!$Q$5 -> 20.484519 | J17: ='1Tarifas Distribuidoras - INPUT'!$Q$5 -> 20.484519 | K17: ='1Tarifas Distribuidoras - INPUT'!$Q$5 -> 20.484519 | L17: ='1Tarifas Distribuidoras - INPUT'!$Q$6 -> 20.117692 | M17: ='1Tarifas Distribuidoras - INPUT'!$Q$6 -> 20.117692 | N17: ='1Tarifas Distribuidoras - INPUT'!$Q$6 -> 20.117692 | O17: ='1Tarifas Distribuidoras - INPUT'!$Q$6 -> 20.117692 | P17: ='1Tarifas Distribuidoras - INPUT'!$Q$6 -> 20.117692
A18: UBU | B18: TUSD FIO / DEMANDA | C18: Fora Ponta | D18: 50610003 | E18: ='1Tarifas Distribuidoras - INPUT'!$V$7 -> 8.3724194 | F18: ='1Tarifas Distribuidoras - INPUT'!$V$7 -> 8.3724194 | G18: ='1Tarifas Distribuidoras - INPUT'!$V$7 -> 8.3724194 | H18: ='1Tarifas Distribuidoras - INPUT'!$V$7 -> 8.3724194 | I18: ='1Tarifas Distribuidoras - INPUT'!$V$7 -> 8.3724194 | J18: ='1Tarifas Distribuidoras - INPUT'!$V$7 -> 8.3724194 | K18: ='1Tarifas Distribuidoras - INPUT'!$E$8 -> 11.691942 | L18: ='1Tarifas Distribuidoras - INPUT'!$V$6 -> 8.5428421 | M18: ='1Tarifas Distribuidoras - INPUT'!$V$6 -> 8.5428421 | N18: ='1Tarifas Distribuidoras - INPUT'!$V$6 -> 8.5428421 | O18: ='1Tarifas Distribuidoras - INPUT'!$V$6 -> 8.5428421 | P18: ='1Tarifas Distribuidoras - INPUT'!$V$6 -> 8.5428421
A19: UBU | B19: TUSD ENCARGO | C19: Encargo Transmis | D19: 50610006
A20: UBU | B20: TUSD ENCARGO | C20: Desconto Enc. G.A. | D20: 50610006 | E20: ='1Tarifas Distribuidoras - INPUT'!$H$5 -> 77.55 | F20: ='1Tarifas Distribuidoras - INPUT'!$H$5 -> 77.55 | G20: ='1Tarifas Distribuidoras - INPUT'!$H$5 -> 77.55 | H20: ='1Tarifas Distribuidoras - INPUT'!$H$5 -> 77.55 | I20: ='1Tarifas Distribuidoras - INPUT'!$H$5 -> 77.55 | J20: ='1Tarifas Distribuidoras - INPUT'!$H$5 -> 77.55 | K20: ='1Tarifas Distribuidoras - INPUT'!$H$5 -> 77.55 | L20: ='1Tarifas Distribuidoras - INPUT'!$H$6 -> 78.620665 | M20: ='1Tarifas Distribuidoras - INPUT'!$H$6 -> 78.620665 | N20: ='1Tarifas Distribuidoras - INPUT'!$H$6 -> 78.620665 | O20: ='1Tarifas Distribuidoras - INPUT'!$H$6 -> 78.620665 | P20: ='1Tarifas Distribuidoras - INPUT'!$H$6 -> 78.620665
A21: UBU | B21: TUSD ENCARGO | C21: Encargo Distribuição | D21: 50610006 | E21: ='1Tarifas Distribuidoras - INPUT'!$AA$5 -> 86.8299 | F21: ='1Tarifas Distribuidoras - INPUT'!$AA$5 -> 86.8299 | G21: ='1Tarifas Distribuidoras - INPUT'!$AA$5 -> 86.8299 | H21: ='1Tarifas Distribuidoras - INPUT'!$AA$5 -> 86.8299 | I21: ='1Tarifas Distribuidoras - INPUT'!$AA$5 -> 86.8299 | J21: ='1Tarifas Distribuidoras - INPUT'!$AA$5 -> 86.8299 | K21: ='1Tarifas Distribuidoras - INPUT'!$AA$5 -> 86.8299 | L21: ='1Tarifas Distribuidoras - INPUT'!$AA$6 -> 83.216102 | M21: ='1Tarifas Distribuidoras - INPUT'!$AA$6 -> 83.216102 | N21: ='1Tarifas Distribuidoras - INPUT'!$AA$6 -> 83.216102 | O21: ='1Tarifas Distribuidoras - INPUT'!$AA$6 -> 83.216102 | P21: ='1Tarifas Distribuidoras - INPUT'!$AA$6 -> 83.216102
A22: ES | B22: Consumo de Energia | C22: PMIX | D22: 50610002 | E22: ='1Tarifas Distribuidoras - INPUT'!$K$23 -> 161.2451 | F22: ='1Tarifas Distribuidoras - INPUT'!$K$23 -> 161.2451 | G22: ='1Tarifas Distribuidoras - INPUT'!$K$23 -> 161.2451 | H22: ='1Tarifas Distribuidoras - INPUT'!$K$23 -> 161.2451 | I22: ='1Tarifas Distribuidoras - INPUT'!$K$23 -> 161.2451 | J22: ='1Tarifas Distribuidoras - INPUT'!$K$23 -> 161.2451 | K22: ='1Tarifas Distribuidoras - INPUT'!$K$23 -> 161.2451 | L22: ='1Tarifas Distribuidoras - INPUT'!$K$23 -> 161.2451 | ... P22: ='1Tarifas Distribuidoras - INPUT'!$K$23 -> 161.2451

Sheet 3Planejamento Produção - INPUT
A1: Volumes (ktms) - Planejado | B1: Jan | C1: Fev | D1: Mar | E1: Abr | F1: Mai | G1: Jun | H1: Jul | I1: Ago | J1: Set | K1: Out | L1: Nov | M1: Dez
A2: Aréa | B2: M1 | C2: M2 | D2: M3 | E2: M4 | F2: M5 | G2: M6 | H2: M7 | I2: M8 | J2: M9 | K2: M10 | L2: M11 | M2: M12
B3: 31 | C3: 28 | D3: 31 | E3: 30 | F3: 31 | G3: 30 | H3: 31 | I3: 31 | J3: 30 | K3: 31 | L3: 30 | M3: 31
A4: Filtragem Germano (Arenoso) | B4: 1059.0685 | C4: 1021.032 | D4: 1004.4547 | E4: 1119.82 | F4: 1137.3517 | G4: 1148.2279 | H4: 1188.5718 | I4: 1138.5113 | J4: 1149.783 | K4: 1159.5339 | L4: 1051.4634 | M4: 1120.4827
A5: Beneficiamento Usina 1 | B5: 0 | C5: 0 | D5: 0 | E5: 0 | F5: 0 | G5: 0 | H5: 0 | I5: 0 | J5: 0 | K5: 0 | L5: 0 | M5: 0
A6: Beneficiamento Usina 2 | B6: 599.77701 | C6: 546.47305 | D6: 576.60359 | E6: 565.60741 | F6: 584.42848 | G6: 619.56526 | H6: 641.88963 | I6: 641.70219 | J6: 624.34908 | K6: 611.98334 | L6: 525.62356 | M6: 585.60584
A7: Beneficiamento Usina 3 | B7: 660.81339 | C7: 683.62185 | D7: 680.47395 | E7: 806.83856 | F7: 828.46327 | G7: 802.19253 | H7: 822.42659 | I7: 751.43493 | J7: 793.45275 | K7: 794.81849 | L7: 734.24252 | M7: 726.84026
A8: Mineroduto 1 | B8: 0 | C8: 0 | D8: 0 | E8: 0 | F8: 0 | G8: 0 | H8: 0 | I8: 0 | J8: 0 | K8: 0 | L8: 0 | M8: 0
A9: Mineroduto 2 | B9: 0 | C9: 0 | D9: 0 | E9: 0 | F9: 0 | G9: 0 | H9: 0 | I9: 0 | J9: 0 | K9: 0 | L9: 0 | M9: 0
A10: Mineroduto 3 | B10: 1260.5904 | C10: 1230.0949 | D10: =1053.1452909432+203.932249053542 -> 1257.0775 | E10: 1372.446 | F10: 1412.8918 | G10: 1421.7578 | H10: 1464.3162 | I10: 1393.1371 | J10: 1417.8018 | K10: 1406.8018 | L10: 1259.8661 | M10: 1312.4461
A11: Preparação 1 | B11: 0 | C11: 0 | D11: 0 | E11: 0 | F11: 0 | G11: 0 | H11: 0 | I11: 0 | J11: 0 | K11: 0 | L11: 0 | M11: 0
A12: Preparação 2 | B12: 1260.5904 | C12: 1230.0949 | D12: 1257.0775 | E12: 1372.446 | F12: 1412.8918 | G12: 1421.7578 | H12: 1464.3162 | I12: 1393.1371 | J12: 1417.8018 | K12: 1406.8018 | L12: 1259.8661 | M12: 1312.4461
A13: Usina 1 | B13: 0 | C13: 0 | D13: 0 | E13: 0 | F13: 0 | G13: 0 | H13: 0 | I13: 0 | J13: 0 | K13: 0 | L13: 0 | M13: 0
A14: Usina 2 | B14: 0 | C14: 0 | D14: 0 | E14: 0 | F14: 0 | G14: 0 | H14: 0 | I14: 0 | J14: 0 | K14: 0 | L14: 0 | M14: 0
A15: Usina 3 | B15: 474.39089 | C15: 457.31995 | D15: 385.05165 | E15: 522.00976 | F15: 527.21094 | G15: 532.46778 | H15: 560.31596 | I15: 527.28544 | J15: 523.74398 | K15: 536.10451 | L15: 471.71974 | M15: 488.46413
A16: Usina 4 | B16: 592.83754 | C16: 551.3311 | D16: 678.84305 | E16: 651.57415 | F16: 637.68127 | G16: 687.99477 | H16: 700.10889 | I16: 636.35485 | J16: 675.2507 | K16: 669.7878 | L16: 565.4284 | M16: 628.82557
A17: Vendas | B17: 1067.2284 | C17: 1008.651 | D17: 1063.8947 | E17: 1173.5839 | F17: 1164.8922 | G17: 1220.4626 | H17: 1260.4248 | I17: 1163.6403 | J17: 1198.9947 | K17: 1205.8923 | L17: 1037.1481 | M17: 1117.2897
A18: Produção PSC + PSM | B18: 143.85506 | C18: 174.65286 | D18: 143.82505 | E18: 144.81226 | F18: 193.95903 | G18: 145.23416 | H18: 145.59382 | I18: 176.04776 | J18: 162.94095 | K18: 145.10303 | L18: 174.90933 | M18: 144.30561
A19: Pellet Feed (embarque) | B19: 385.92688 | C19: 385.92688 | D19: 385.92688 | E19: 385.92688 | F19: 385.92688 | G19: 385.92688 | H19: 385.92688 | I19: 385.92688 | J19: 385.92688 | K19: 385.92688 | L19: 385.92688 | M19: 385.92688
A21: Os dados dessa planilha são todos imputados por cada área. Assim, alguém de área de produção deverá cadastrar todos os dados presentees nessa planilha.

Sheet 4Produção - OCULTA
B1: Produção por mês em tms ( tonelada métrica seca)
A2: Área | B2: Jan | C2: Fev | D2: Mar | E2: Abr | F2: Mai | G2: Jun | H2: Jul | I2: Ago | J2: Set | K2: Out | L2: Nov | M2: Dez
A3: Filtragem Germano (Arenoso) | B3: ='3Planejamento Produção - INPUT'!B4*$B$20 -> 1059068.5 | C3: ='3Planejamento Produção - INPUT'!C4*$B$20 -> 1021032 | D3: ='3Planejamento Produção - INPUT'!D4*$B$20 -> 1004454.7 | E3: ='3Planejamento Produção - INPUT'!E4*$B$20 -> 1119820 | F3: ='3Planejamento Produção - INPUT'!F4*$B$20 -> 1137351.7 | G3: ='3Planejamento Produção - INPUT'!G4*$B$20 -> 1148227.9 | H3: ='3Planejamento Produção - INPUT'!H4*$B$20 -> 1188571.8 | I3: ='3Planejamento Produção - INPUT'!I4*$B$20 -> 1138511.3 | ... M3: ='3Planejamento Produção - INPUT'!M4*$B$20 -> 1120482.7
A4: Beneficiamento Usina 1 | B4: ='3Planejamento Produção - INPUT'!B5*$B$20 -> 0 | C4: ='3Planejamento Produção - INPUT'!C5*$B$20 -> 0 | D4: ='3Planejamento Produção - INPUT'!D5*$B$20 -> 0 | E4: ='3Planejamento Produção - INPUT'!E5*$B$20 -> 0 | F4: ='3Planejamento Produção - INPUT'!F5*$B$20 -> 0 | G4: ='3Planejamento Produção - INPUT'!G5*$B$20 -> 0 | H4: ='3Planejamento Produção - INPUT'!H5*$B$20 -> 0 | I4: ='3Planejamento Produção - INPUT'!I5*$B$20 -> 0 | ... M4: ='3Planejamento Produção - INPUT'!M5*$B$20 -> 0
A5: Beneficiamento Usina 2 | B5: ='3Planejamento Produção - INPUT'!B6*$B$20 -> 599777.01 | C5: ='3Planejamento Produção - INPUT'!C6*$B$20 -> 546473.05 | D5: ='3Planejamento Produção - INPUT'!D6*$B$20 -> 576603.59 | E5: ='3Planejamento Produção - INPUT'!E6*$B$20 -> 565607.41 | F5: ='3Planejamento Produção - INPUT'!F6*$B$20 -> 584428.48 | G5: ='3Planejamento Produção - INPUT'!G6*$B$20 -> 619565.26 | H5: ='3Planejamento Produção - INPUT'!H6*$B$20 -> 641889.63 | I5: ='3Planejamento Produção - INPUT'!I6*$B$20 -> 641702.19 | ... M5: ='3Planejamento Produção - INPUT'!M6*$B$20 -> 585605.84
A6: Beneficiamento Usina 3 | B6: ='3Planejamento Produção - INPUT'!B7*$B$20 -> 660813.39 | C6: ='3Planejamento Produção - INPUT'!C7*$B$20 -> 683621.85 | D6: ='3Planejamento Produção - INPUT'!D7*$B$20 -> 680473.95 | E6: ='3Planejamento Produção - INPUT'!E7*$B$20 -> 806838.56 | F6: ='3Planejamento Produção - INPUT'!F7*$B$20 -> 828463.27 | G6: ='3Planejamento Produção - INPUT'!G7*$B$20 -> 802192.53 | H6: ='3Planejamento Produção - INPUT'!H7*$B$20 -> 822426.59 | I6: ='3Planejamento Produção - INPUT'!I7*$B$20 -> 751434.93 | ... M6: ='3Planejamento Produção - INPUT'!M7*$B$20 -> 726840.26
A7: Mineroduto 1 | B7: ='3Planejamento Produção - INPUT'!B8*$B$20 -> 0 | C7: ='3Planejamento Produção - INPUT'!C8*$B$20 -> 0 | D7: ='3Planejamento Produção - INPUT'!D8*$B$20 -> 0 | E7: ='3Planejamento Produção - INPUT'!E8*$B$20 -> 0 | F7: ='3Planejamento Produção - INPUT'!F8*$B$20 -> 0 | G7: ='3Planejamento Produção - INPUT'!G8*$B$20 -> 0 | H7: ='3Planejamento Produção - INPUT'!H8*$B$20 -> 0 | I7: ='3Planejamento Produção - INPUT'!I8*$B$20 -> 0 | ... M7: ='3Planejamento Produção - INPUT'!M8*$B$20 -> 0
A8: Mineroduto 2 | B8: ='3Planejamento Produção - INPUT'!B9*$B$20 -> 0 | C8: ='3Planejamento Produção - INPUT'!C9*$B$20 -> 0 | D8: ='3Planejamento Produção - INPUT'!D9*$B$20 -> 0 | E8: ='3Planejamento Produção - INPUT'!E9*$B$20 -> 0 | F8: ='3Planejamento Produção - INPUT'!F9*$B$20 -> 0 | G8: ='3Planejamento Produção - INPUT'!G9*$B$20 -> 0 | H8: ='3Planejamento Produção - INPUT'!H9*$B$20 -> 0 | I8: ='3Planejamento Produção - INPUT'!I9*$B$20 -> 0 | ... M8: ='3Planejamento Produção - INPUT'!M9*$B$20 -> 0
A9: Mineroduto 3 | B9: ='3Planejamento Produção - INPUT'!B10*$B$20 -> 1260590.4 | C9: ='3Planejamento Produção - INPUT'!C10*$B$20 -> 1230094.9 | D9: ='3Planejamento Produção - INPUT'!D10*$B$20 -> 1257077.5 | E9: ='3Planejamento Produção - INPUT'!E10*$B$20 -> 1372446 | F9: ='3Planejamento Produção - INPUT'!F10*$B$20 -> 1412891.8 | G9: ='3Planejamento Produção - INPUT'!G10*$B$20 -> 1421757.8 | H9: ='3Planejamento Produção - INPUT'!H10*$B$20 -> 1464316.2 | I9: ='3Planejamento Produção - INPUT'!I10*$B$20 -> 1393137.1 | ... M9: ='3Planejamento Produção - INPUT'!M10*$B$20 -> 1312446.1
A10: Preparação 1 | B10: ='3Planejamento Produção - INPUT'!B11*$B$20 -> 0 | C10: ='3Planejamento Produção - INPUT'!C11*$B$20 -> 0 | D10: ='3Planejamento Produção - INPUT'!D11*$B$20 -> 0 | E10: ='3Planejamento Produção - INPUT'!E11*$B$20 -> 0 | F10: ='3Planejamento Produção - INPUT'!F11*$B$20 -> 0 | G10: ='3Planejamento Produção - INPUT'!G11*$B$20 -> 0 | H10: ='3Planejamento Produção - INPUT'!H11*$B$20 -> 0 | I10: ='3Planejamento Produção - INPUT'!I11*$B$20 -> 0 | ... M10: ='3Planejamento Produção - INPUT'!M11*$B$20 -> 0
A11: Preparação 2 | B11: ='3Planejamento Produção - INPUT'!B12*$B$20 -> 1260590.4 | C11: ='3Planejamento Produção - INPUT'!C12*$B$20 -> 1230094.9 | D11: ='3Planejamento Produção - INPUT'!D12*$B$20 -> 1257077.5 | E11: ='3Planejamento Produção - INPUT'!E12*$B$20 -> 1372446 | F11: ='3Planejamento Produção - INPUT'!F12*$B$20 -> 1412891.8 | G11: ='3Planejamento Produção - INPUT'!G12*$B$20 -> 1421757.8 | H11: ='3Planejamento Produção - INPUT'!H12*$B$20 -> 1464316.2 | I11: ='3Planejamento Produção - INPUT'!I12*$B$20 -> 1393137.1 | ... M11: ='3Planejamento Produção - INPUT'!M12*$B$20 -> 1312446.1
A12: Usina 1 | B12: ='3Planejamento Produção - INPUT'!B13*$B$20 -> 0 | C12: ='3Planejamento Produção - INPUT'!C13*$B$20 -> 0 | D12: ='3Planejamento Produção - INPUT'!D13*$B$20 -> 0 | E12: ='3Planejamento Produção - INPUT'!E13*$B$20 -> 0 | F12: ='3Planejamento Produção - INPUT'!F13*$B$20 -> 0 | G12: ='3Planejamento Produção - INPUT'!G13*$B$20 -> 0 | H12: ='3Planejamento Produção - INPUT'!H13*$B$20 -> 0 | I12: ='3Planejamento Produção - INPUT'!I13*$B$20 -> 0 | ... M12: ='3Planejamento Produção - INPUT'!M13*$B$20 -> 0
A13: Usina 2 | B13: ='3Planejamento Produção - INPUT'!B14*$B$20 -> 0 | C13: ='3Planejamento Produção - INPUT'!C14*$B$20 -> 0 | D13: ='3Planejamento Produção - INPUT'!D14*$B$20 -> 0 | E13: ='3Planejamento Produção - INPUT'!E14*$B$20 -> 0 | F13: ='3Planejamento Produção - INPUT'!F14*$B$20 -> 0 | G13: ='3Planejamento Produção - INPUT'!G14*$B$20 -> 0 | H13: ='3Planejamento Produção - INPUT'!H14*$B$20 -> 0 | I13: ='3Planejamento Produção - INPUT'!I14*$B$20 -> 0 | ... M13: ='3Planejamento Produção - INPUT'!M14*$B$20 -> 0
A14: Usina 3 | B14: ='3Planejamento Produção - INPUT'!B15*$B$20 -> 474390.89 | C14: ='3Planejamento Produção - INPUT'!C15*$B$20 -> 457319.95 | D14: ='3Planejamento Produção - INPUT'!D15*$B$20 -> 385051.65 | E14: ='3Planejamento Produção - INPUT'!E15*$B$20 -> 522009.76 | F14: ='3Planejamento Produção - INPUT'!F15*$B$20 -> 527210.94 | G14: ='3Planejamento Produção - INPUT'!G15*$B$20 -> 532467.78 | H14: ='3Planejamento Produção - INPUT'!H15*$B$20 -> 560315.96 | I14: ='3Planejamento Produção - INPUT'!I15*$B$20 -> 527285.44 | ... M14: ='3Planejamento Produção - INPUT'!M15*$B$20 -> 488464.13
... A18: Pellet Feed (embarque) | B18: ='3Planejamento Produção - INPUT'!B19*$B$20 -> 385926.88 | C18: ='3Planejamento Produção - INPUT'!C19*$B$20 -> 385926.88 | D18: ='3Planejamento Produção - INPUT'!D19*$B$20 -> 385926.88 | E18: ='3Planejamento Produção - INPUT'!E19*$B$20 -> 385926.88 | F18: ='3Planejamento Produção - INPUT'!F19*$B$20 -> 385926.88 | G18: ='3Planejamento Produção - INPUT'!G19*$B$20 -> 385926.88 | H18: ='3Planejamento Produção - INPUT'!H19*$B$20 -> 385926.88 | I18: ='3Planejamento Produção - INPUT'!I19*$B$20 -> 385926.88 | ... M18: ='3Planejamento Produção - INPUT'!M19*$B$20 -> 385926.88
A20: Multiplicador | B20: 1000

Sheet 5Plan Consumo Especifico -INPUT
A1: PLANEJADO | B1: Consumo Específico de Energia Elétrica (kWh/tms)
A2: Área | B2: 46023 | C2: =B2 + 35 -> 46058 | D2: =C2 + 30 -> 46088 | E2: =D2 + 30 -> 46118 | F2: =E2 + 30 -> 46148 | G2: =F2 + 30 -> 46178 | H2: =G2 + 30 -> 46208 | I2: =H2 + 30 -> 46238 | J2: =I2 + 30 -> 46268 | K2: =J2 + 30 -> 46298 | ... M2: =L2 + 30 -> 46358
A3: Filtragem Germano | B3: 3.2782218 | C3: 3.3594929 | D3: 3.2873827 | E3: 3.0110439 | F3: 2.924849 | G3: 2.9066097 | H3: 2.8221329 | I3: 2.9663232 | J3: 2.9147197 | K3: 2.9375104 | L3: 3.2801066 | M3: 3.1486969
A4: Mineração | B4: 1.484089 | C4: 1.3742516 | D4: 1.4888116 | E4: 1.3200199 | F4: 1.3244418 | G4: 1.2736057 | H4: 1.2783034 | I4: 1.3434574 | J4: 1.2771984 | K4: 1.3300897 | L4: 1.437355 | M4: 1.4263995
A5: Beneficiamento 1
A6: Beneficiamento 2 | B6: 42.39599 | C6: 46.531371 | D6: 44.099864 | E6: 44.957226 | F6: 43.509413 | G6: 41.041908 | H6: 39.614505 | I6: 39.626077 | J6: 40.727441 | K6: 41.55038 | L6: 48.377094 | M6: 43.421937
A7: Beneficiamento 3 | B7: 42.214994 | C7: 40.806527 | D7: 40.9953 | E7: 34.57474 | F7: 33.672263 | G7: 34.774985 | H7: 33.91942 | I7: 37.123951 | J7: 35.158027 | K7: 35.097615 | L7: 37.993214 | M7: 38.380143
A8: Brumal
A9: Mineroduto 1
A10: Mineroduto 2
A11: Mineroduto 3 | B11: 7.1050642 | C11: 7.1923077 | D11: 7.558579 | E11: 7.1050642 | F11: 7.0579495 | G11: 7.1972582 | H11: 7.1267817 | I11: 7.18065 | J11: 7.1050642 | K11: 7.18065 | L11: 7.1428571 | M11: 7.18065
A12: Preparação 1 | B12: 0 | C12: 0 | D12: 0 | E12: 0 | F12: 0 | G12: 0 | H12: 0 | I12: 0 | J12: 0 | K12: 0 | L12: 0 | M12: 0
A13: Preparação 2 | B13: 10.77 | C13: 10.77 | D13: 10.77 | E13: 10.77 | F13: 10.77 | G13: 10.77 | H13: 10.77 | I13: 10.77 | J13: 10.77 | K13: 10.77 | L13: 10.77 | M13: 10.77
A14: Usina 1
A15: Usina 2
A16: Usina 3 | B16: 29.95 | C16: 29.95 | D16: 29.95 | E16: 29.95 | F16: 29.95 | G16: 29.95 | H16: 29.95 | I16: 29.95 | J16: 29.95 | K16: 29.95 | L16: 29.95 | M16: 29.95
A17: Usina 4 | B17: 32.17 | C17: 32.17 | D17: 32.17 | E17: 32.17 | F17: 32.17 | G17: 32.17 | H17: 32.17 | I17: 32.17 | J17: 32.17 | K17: 32.17 | L17: 32.17 | M17: 32.17
A18: Estocagem | B18: 0.86881696 | C18: 0.86881696 | D18: 0.86881696 | E18: 0.86881696 | F18: 0.86881696 | G18: 0.86881696 | H18: 0.86881696 | I18: 0.86881696 | J18: 0.86881696 | K18: 0.86881696 | L18: 0.86881696 | M18: 0.86881696
A20: Os dados dessa planilha são todos imputados por cada área. Assim, alguém de área de consumo deverá cadastrar todos os dados presentees nessa planilha.

Sheet 6Consumo Especifico - OCULTA
C1: Consumo planejado por mês
A2: Centro de Custo | B2: Área | C2: Jan | D2: Fev | E2: Mar | F2: Abr | G2: Mai | H2: Jun | I2: Jul | J2: Ago | K2: Set | L2: Out | M2: Nov | N2: Dez
A3: 11140030 | B3: Filtragem Germano | C3: ='5Plan Consumo Especifico -INPUT'!B3 -> 3.2782218 | D3: ='5Plan Consumo Especifico -INPUT'!C3 -> 3.3594929 | E3: ='5Plan Consumo Especifico -INPUT'!D3 -> 3.2873827 | F3: ='5Plan Consumo Especifico -INPUT'!E3 -> 3.0110439 | G3: ='5Plan Consumo Especifico -INPUT'!F3 -> 2.924849 | H3: ='5Plan Consumo Especifico -INPUT'!G3 -> 2.9066097 | I3: ='5Plan Consumo Especifico -INPUT'!H3 -> 2.8221329 | J3: ='5Plan Consumo Especifico -INPUT'!I3 -> 2.9663232 | ... N3: ='5Plan Consumo Especifico -INPUT'!M3 -> 3.1486969
A4: 11110060 | B4: Mineração 1 | C4: ='5Plan Consumo Especifico -INPUT'!B4 -> 1.484089 | D4: ='5Plan Consumo Especifico -INPUT'!C4 -> 1.3742516 | E4: ='5Plan Consumo Especifico -INPUT'!D4 -> 1.4888116 | F4: ='5Plan Consumo Especifico -INPUT'!E4 -> 1.3200199 | G4: ='5Plan Consumo Especifico -INPUT'!F4 -> 1.3244418 | H4: ='5Plan Consumo Especifico -INPUT'!G4 -> 1.2736057 | I4: ='5Plan Consumo Especifico -INPUT'!H4 -> 1.2783034 | J4: ='5Plan Consumo Especifico -INPUT'!I4 -> 1.3434574 | ... N4: ='5Plan Consumo Especifico -INPUT'!M4 -> 1.4263995
A5: 11130180 | B5: Beneficiamento 1 | C5: ='5Plan Consumo Especifico -INPUT'!B5 -> 0 | D5: ='5Plan Consumo Especifico -INPUT'!C5 -> 0 | E5: ='5Plan Consumo Especifico -INPUT'!D5 -> 0 | F5: ='5Plan Consumo Especifico -INPUT'!E5 -> 0 | G5: ='5Plan Consumo Especifico -INPUT'!F5 -> 0 | H5: ='5Plan Consumo Especifico -INPUT'!G5 -> 0 | I5: ='5Plan Consumo Especifico -INPUT'!H5 -> 0 | J5: ='5Plan Consumo Especifico -INPUT'!I5 -> 0 | ... N5: ='5Plan Consumo Especifico -INPUT'!M5 -> 0
A6: 11131180 | B6: Beneficiamento 2 | C6: ='5Plan Consumo Especifico -INPUT'!B6 -> 42.39599 | D6: ='5Plan Consumo Especifico -INPUT'!C6 -> 46.531371 | E6: ='5Plan Consumo Especifico -INPUT'!D6 -> 44.099864 | F6: ='5Plan Consumo Especifico -INPUT'!E6 -> 44.957226 | G6: ='5Plan Consumo Especifico -INPUT'!F6 -> 43.509413 | H6: ='5Plan Consumo Especifico -INPUT'!G6 -> 41.041908 | I6: ='5Plan Consumo Especifico -INPUT'!H6 -> 39.614505 | J6: ='5Plan Consumo Especifico -INPUT'!I6 -> 39.626077 | ... N6: ='5Plan Consumo Especifico -INPUT'!M6 -> 43.421937
A7: 11132180 | B7: Beneficiamento 3 | C7: ='5Plan Consumo Especifico -INPUT'!B7 -> 42.214994 | D7: ='5Plan Consumo Especifico -INPUT'!C7 -> 40.806527 | E7: ='5Plan Consumo Especifico -INPUT'!D7 -> 40.9953 | F7: ='5Plan Consumo Especifico -INPUT'!E7 -> 34.57474 | G7: ='5Plan Consumo Especifico -INPUT'!F7 -> 33.672263 | H7: ='5Plan Consumo Especifico -INPUT'!G7 -> 34.774985 | I7: ='5Plan Consumo Especifico -INPUT'!H7 -> 33.91942 | J7: ='5Plan Consumo Especifico -INPUT'!I7 -> 37.123951 | ... N7: ='5Plan Consumo Especifico -INPUT'!M7 -> 38.380143
A8: 11162040 | B8: Mineroduto 1 | C8: ='5Plan Consumo Especifico -INPUT'!B9 -> 0 | D8: ='5Plan Consumo Especifico -INPUT'!C9 -> 0 | E8: ='5Plan Consumo Especifico -INPUT'!D9 -> 0 | F8: ='5Plan Consumo Especifico -INPUT'!E9 -> 0 | G8: ='5Plan Consumo Especifico -INPUT'!F9 -> 0 | H8: ='5Plan Consumo Especifico -INPUT'!G9 -> 0 | I8: ='5Plan Consumo Especifico -INPUT'!H9 -> 0 | J8: ='5Plan Consumo Especifico -INPUT'!I9 -> 0 | ... N8: ='5Plan Consumo Especifico -INPUT'!M9 -> 0
A9: 11162090 | B9: Mineroduto 2 | C9: ='5Plan Consumo Especifico -INPUT'!B10 -> 0 | D9: ='5Plan Consumo Especifico -INPUT'!C10 -> 0 | E9: ='5Plan Consumo Especifico -INPUT'!D10 -> 0 | F9: ='5Plan Consumo Especifico -INPUT'!E10 -> 0 | G9: ='5Plan Consumo Especifico -INPUT'!F10 -> 0 | H9: ='5Plan Consumo Especifico -INPUT'!G10 -> 0 | I9: ='5Plan Consumo Especifico -INPUT'!H10 -> 0 | J9: ='5Plan Consumo Especifico -INPUT'!I10 -> 0 | ... N9: ='5Plan Consumo Especifico -INPUT'!M10 -> 0
A10: 11162120 | B10: Mineroduto 3 | C10: ='5Plan Consumo Especifico -INPUT'!B11 -> 7.1050642 | D10: ='5Plan Consumo Especifico -INPUT'!C11 -> 7.1923077 | E10: ='5Plan Consumo Especifico -INPUT'!D11 -> 7.558579 | F10: ='5Plan Consumo Especifico -INPUT'!E11 -> 7.1050642 | G10: ='5Plan Consumo Especifico -INPUT'!F11 -> 7.0579495 | H10: ='5Plan Consumo Especifico -INPUT'!G11 -> 7.1972582 | I10: ='5Plan Consumo Especifico -INPUT'!H11 -> 7.1267817 | J10: ='5Plan Consumo Especifico -INPUT'!I11 -> 7.18065 | ... N10: ='5Plan Consumo Especifico -INPUT'!M11 -> 7.18065
A11: 12110080 | B11: Preparação 1 | C11: ='5Plan Consumo Especifico -INPUT'!B12 -> 0 | D11: ='5Plan Consumo Especifico -INPUT'!C12 -> 0 | E11: ='5Plan Consumo Especifico -INPUT'!D12 -> 0 | F11: ='5Plan Consumo Especifico -INPUT'!E12 -> 0 | G11: ='5Plan Consumo Especifico -INPUT'!F12 -> 0 | H11: ='5Plan Consumo Especifico -INPUT'!G12 -> 0 | I11: ='5Plan Consumo Especifico -INPUT'!H12 -> 0 | J11: ='5Plan Consumo Especifico -INPUT'!I12 -> 0 | ... N11: ='5Plan Consumo Especifico -INPUT'!M12 -> 0
A12: 12111080 | B12: Preparação 2 | C12: ='5Plan Consumo Especifico -INPUT'!B13 -> 10.77 | D12: ='5Plan Consumo Especifico -INPUT'!C13 -> 10.77 | E12: ='5Plan Consumo Especifico -INPUT'!D13 -> 10.77 | F12: ='5Plan Consumo Especifico -INPUT'!E13 -> 10.77 | G12: ='5Plan Consumo Especifico -INPUT'!F13 -> 10.77 | H12: ='5Plan Consumo Especifico -INPUT'!G13 -> 10.77 | I12: ='5Plan Consumo Especifico -INPUT'!H13 -> 10.77 | J12: ='5Plan Consumo Especifico -INPUT'!I13 -> 10.77 | ... N12: ='5Plan Consumo Especifico -INPUT'!M13 -> 10.77
A13: 12133040 | B13: Usina 1 | C13: ='5Plan Consumo Especifico -INPUT'!B14 -> 0 | D13: ='5Plan Consumo Especifico -INPUT'!C14 -> 0 | E13: ='5Plan Consumo Especifico -INPUT'!D14 -> 0 | F13: ='5Plan Consumo Especifico -INPUT'!E14 -> 0 | G13: ='5Plan Consumo Especifico -INPUT'!F14 -> 0 | H13: ='5Plan Consumo Especifico -INPUT'!G14 -> 0 | I13: ='5Plan Consumo Especifico -INPUT'!H14 -> 0 | J13: ='5Plan Consumo Especifico -INPUT'!I14 -> 0 | ... N13: ='5Plan Consumo Especifico -INPUT'!M14 -> 0
A14: 12135040 | B14: Usina 2 | C14: ='5Plan Consumo Especifico -INPUT'!B15 -> 0 | D14: ='5Plan Consumo Especifico -INPUT'!C15 -> 0 | E14: ='5Plan Consumo Especifico -INPUT'!D15 -> 0 | F14: ='5Plan Consumo Especifico -INPUT'!E15 -> 0 | G14: ='5Plan Consumo Especifico -INPUT'!F15 -> 0 | H14: ='5Plan Consumo Especifico -INPUT'!G15 -> 0 | I14: ='5Plan Consumo Especifico -INPUT'!H15 -> 0 | J14: ='5Plan Consumo Especifico -INPUT'!I15 -> 0 | ... N14: ='5Plan Consumo Especifico -INPUT'!M15 -> 0
A15: 12136040 | B15: Usina 3 | C15: ='5Plan Consumo Especifico -INPUT'!B16 -> 29.95 | D15: ='5Plan Consumo Especifico -INPUT'!C16 -> 29.95 | E15: ='5Plan Consumo Especifico -INPUT'!D16 -> 29.95 | F15: ='5Plan Consumo Especifico -INPUT'!E16 -> 29.95 | G15: ='5Plan Consumo Especifico -INPUT'!F16 -> 29.95 | H15: ='5Plan Consumo Especifico -INPUT'!G16 -> 29.95 | I15: ='5Plan Consumo Especifico -INPUT'!H16 -> 29.95 | J15: ='5Plan Consumo Especifico -INPUT'!I16 -> 29.95 | ... N15: ='5Plan Consumo Especifico -INPUT'!M16 -> 29.95
A16: 12138040 | B16: Usina 4 | C16: ='5Plan Consumo Especifico -INPUT'!B17 -> 32.17 | D16: ='5Plan Consumo Especifico -INPUT'!C17 -> 32.17 | E16: ='5Plan Consumo Especifico -INPUT'!D17 -> 32.17 | F16: ='5Plan Consumo Especifico -INPUT'!E17 -> 32.17 | G16: ='5Plan Consumo Especifico -INPUT'!F17 -> 32.17 | H16: ='5Plan Consumo Especifico -INPUT'!G17 -> 32.17 | I16: ='5Plan Consumo Especifico -INPUT'!H17 -> 32.17 | J16: ='5Plan Consumo Especifico -INPUT'!I17 -> 32.17 | ... N16: ='5Plan Consumo Especifico -INPUT'!M17 -> 32.17
A17: 12420080 | B17: Estocagem | C17: ='5Plan Consumo Especifico -INPUT'!B18 -> 0.86881696 | D17: ='5Plan Consumo Especifico -INPUT'!C18 -> 0.86881696 | E17: ='5Plan Consumo Especifico -INPUT'!D18 -> 0.86881696 | F17: ='5Plan Consumo Especifico -INPUT'!E18 -> 0.86881696 | G17: ='5Plan Consumo Especifico -INPUT'!F18 -> 0.86881696 | H17: ='5Plan Consumo Especifico -INPUT'!G18 -> 0.86881696 | I17: ='5Plan Consumo Especifico -INPUT'!H18 -> 0.86881696 | J17: ='5Plan Consumo Especifico -INPUT'!I18 -> 0.86881696 | ... N17: ='5Plan Consumo Especifico -INPUT'!M18 -> 0.86881696

Sheet 7Consumo Área - CALC
C1: Consumo planejado por mês
A2: Centro de Custo | B2: Área | C2: Jan | D2: Fev | E2: Mar | F2: Abr | G2: Mai | H2: Jun | I2: Jul | J2: Ago | K2: Set | L2: Out | M2: Nov | N2: Dez | O2: Planejado
A3: 11140030 | B3: Filtragem Germano | C3: ='6Consumo Especifico - OCULTA'!C3*'4Produção - OCULTA'!B3 -> 3471861.4 | D3: ='6Consumo Especifico - OCULTA'!D3*'4Produção - OCULTA'!C3 -> 3430149.9 | E3: ='6Consumo Especifico - OCULTA'!E3*'4Produção - OCULTA'!D3 -> 3302027 | F3: ='6Consumo Especifico - OCULTA'!F3*'4Produção - OCULTA'!E3 -> 3371827.1 | G3: ='6Consumo Especifico - OCULTA'!G3*'4Produção - OCULTA'!F3 -> 3326581.9 | H3: ='6Consumo Especifico - OCULTA'!H3*'4Produção - OCULTA'!G3 -> 3337450.4 | I3: ='6Consumo Especifico - OCULTA'!I3*'4Produção - OCULTA'!H3 -> 3354307.5 | J3: ='6Consumo Especifico - OCULTA'!J3*'4Produção - OCULTA'!I3 -> 3377192.5 | ... N3: ='6Consumo Especifico - OCULTA'!N3*'4Produção - OCULTA'!M3 -> 3528060.5 | O3: =SUM(C3:N3) -> 40705808
A4: 11110060 | B4: Mineração 1 | C4: =('4Produção - OCULTA'!B4+'4Produção - OCULTA'!B5+'4Produção - OCULTA'!B6)*'6Consumo Especifico - OCULTA'!C4 -> 1870828.3 | D4: =('4Produção - OCULTA'!C4+'4Produção - OCULTA'!C5+'4Produção - OCULTA'!C6)*'6Consumo Especifico - OCULTA'!D4 -> 1690459.9 | E4: =('4Produção - OCULTA'!D4+'4Produção - OCULTA'!D5+'4Produção - OCULTA'!D6)*'6Consumo Especifico - OCULTA'!E4 -> 1871551.6 | F4: =('4Produção - OCULTA'!E4+'4Produção - OCULTA'!E5+'4Produção - OCULTA'!E6)*'6Consumo Especifico - OCULTA'!F4 -> 1811656 | G4: =('4Produção - OCULTA'!F4+'4Produção - OCULTA'!F5+'4Produção - OCULTA'!F6)*'6Consumo Especifico - OCULTA'!G4 -> 1871292.8 | H4: =('4Produção - OCULTA'!G4+'4Produção - OCULTA'!G5+'4Produção - OCULTA'!G6)*'6Consumo Especifico - OCULTA'!H4 -> 1810758.8 | I4: =('4Produção - OCULTA'!H4+'4Produção - OCULTA'!H5+'4Produção - OCULTA'!H6)*'6Consumo Especifico - OCULTA'!I4 -> 1871840.4 | J4: =('4Produção - OCULTA'!I4+'4Produção - OCULTA'!I5+'4Produção - OCULTA'!I6)*'6Consumo Especifico - OCULTA'!J4 -> 1871620.4 | ... N4: =('4Produção - OCULTA'!M4+'4Produção - OCULTA'!M5+'4Produção - OCULTA'!M6)*'6Consumo Especifico - OCULTA'!N4 -> 1872072.5 | O4: =SUM(C4:N4) -> 22034942
A5: 11130180 | B5: Beneficiamento 1 | C5: 1040115.7 | D5: 1040115.7 | E5: 1040115.7 | F5: 1040115.7 | G5: 1040115.7 | H5: 1040115.7 | I5: 1040115.7 | J5: 1040115.7 | K5: 1040115.7 | L5: 1040115.7 | M5: 1040115.7 | N5: 1040115.7 | O5: =SUM(C5:N5) -> 12481388
A6: 11131180 | B6: Beneficiamento 2 | C6: ='6Consumo Especifico - OCULTA'!C6*'4Produção - OCULTA'!B5 -> 25428140 | D6: ='6Consumo Especifico - OCULTA'!D6*'4Produção - OCULTA'!C5 -> 25428140 | E6: ='6Consumo Especifico - OCULTA'!E6*'4Produção - OCULTA'!D5 -> 25428140 | F6: ='6Consumo Especifico - OCULTA'!F6*'4Produção - OCULTA'!E5 -> 25428140 | G6: ='6Consumo Especifico - OCULTA'!G6*'4Produção - OCULTA'!F5 -> 25428140 | H6: ='6Consumo Especifico - OCULTA'!H6*'4Produção - OCULTA'!G5 -> 25428140 | I6: ='6Consumo Especifico - OCULTA'!I6*'4Produção - OCULTA'!H5 -> 25428140 | J6: ='6Consumo Especifico - OCULTA'!J6*'4Produção - OCULTA'!I5 -> 25428140 | ... N6: ='6Consumo Especifico - OCULTA'!N6*'4Produção - OCULTA'!M5 -> 25428140 | O6: =SUM(C6:N6) -> 305137683
A7: 11132180 | B7: Beneficiamento 3 | C7: ='6Consumo Especifico - OCULTA'!C7*'4Produção - OCULTA'!B6 -> 27896233 | D7: ='6Consumo Especifico - OCULTA'!D7*'4Produção - OCULTA'!C6 -> 27896233 | E7: ='6Consumo Especifico - OCULTA'!E7*'4Produção - OCULTA'!D6 -> 27896233 | F7: ='6Consumo Especifico - OCULTA'!F7*'4Produção - OCULTA'!E6 -> 27896233 | G7: ='6Consumo Especifico - OCULTA'!G7*'4Produção - OCULTA'!F6 -> 27896233 | H7: ='6Consumo Especifico - OCULTA'!H7*'4Produção - OCULTA'!G6 -> 27896233 | I7: ='6Consumo Especifico - OCULTA'!I7*'4Produção - OCULTA'!H6 -> 27896233 | J7: ='6Consumo Especifico - OCULTA'!J7*'4Produção - OCULTA'!I6 -> 27896233 | ... N7: ='6Consumo Especifico - OCULTA'!N7*'4Produção - OCULTA'!M6 -> 27896233 | O7: =SUM(C7:N7) -> 334754799
A8: 11162040 | B8: Mineroduto 1 | C8: 230000 | D8: 210000 | E8: 230000 | F8: 225000 | G8: 210000 | H8: 230000 | I8: 225000 | J8: 230000 | K8: 230000 | L8: 230000 | M8: 225000 | N8: 230000 | O8: =SUM(C8:N8) -> 2705000
A9: 11162090 | B9: Mineroduto 2 | C9: ='6Consumo Especifico - OCULTA'!C9*'4Produção - OCULTA'!B8 -> 0 | D9: ='6Consumo Especifico - OCULTA'!D9*'4Produção - OCULTA'!C8 -> 0 | E9: ='6Consumo Especifico - OCULTA'!E9*'4Produção - OCULTA'!D8 -> 0 | F9: ='6Consumo Especifico - OCULTA'!F9*'4Produção - OCULTA'!E8 -> 0 | G9: ='6Consumo Especifico - OCULTA'!G9*'4Produção - OCULTA'!F8 -> 0 | H9: ='6Consumo Especifico - OCULTA'!H9*'4Produção - OCULTA'!G8 -> 0 | I9: ='6Consumo Especifico - OCULTA'!I9*'4Produção - OCULTA'!H8 -> 0 | J9: ='6Consumo Especifico - OCULTA'!J9*'4Produção - OCULTA'!I8 -> 0 | ... O9: ='6Consumo Especifico - OCULTA'!O9*'4Produção - OCULTA'!N8 -> 0
A10: 11162120 | B10: Mineroduto 3 | C10: ='6Consumo Especifico - OCULTA'!C10*'4Produção - OCULTA'!B9 -> 8956575.8 | D10: ='6Consumo Especifico - OCULTA'!D10*'4Produção - OCULTA'!C9 -> 8847221 | E10: ='6Consumo Especifico - OCULTA'!E10*'4Produção - OCULTA'!D9 -> 9501719.9 | F10: ='6Consumo Especifico - OCULTA'!F10*'4Produção - OCULTA'!E9 -> 9751316.8 | G10: ='6Consumo Especifico - OCULTA'!G10*'4Produção - OCULTA'!F9 -> 9972118.6 | H10: ='6Consumo Especifico - OCULTA'!H10*'4Produção - OCULTA'!G9 -> 10232758 | I10: ='6Consumo Especifico - OCULTA'!I10*'4Produção - OCULTA'!H9 -> 10435862 | J10: ='6Consumo Especifico - OCULTA'!J10*'4Produção - OCULTA'!I9 -> 10003630 | ... N10: ='6Consumo Especifico - OCULTA'!N10*'4Produção - OCULTA'!M9 -> 9424216.2 | O10: =SUM(C10:N10) -> 1.1629979e+08
A11: 12110080 | B11: Preparação 1 | C11: ='6Consumo Especifico - OCULTA'!C11*'4Produção - OCULTA'!B10 -> 0 | D11: ='6Consumo Especifico - OCULTA'!D11*'4Produção - OCULTA'!C10 -> 0 | E11: ='6Consumo Especifico - OCULTA'!E11*'4Produção - OCULTA'!D10 -> 0 | F11: ='6Consumo Especifico - OCULTA'!F11*'4Produção - OCULTA'!E10 -> 0 | G11: ='6Consumo Especifico - OCULTA'!G11*'4Produção - OCULTA'!F10 -> 0 | H11: ='6Consumo Especifico - OCULTA'!H11*'4Produção - OCULTA'!G10 -> 0 | I11: ='6Consumo Especifico - OCULTA'!I11*'4Produção - OCULTA'!H10 -> 0 | J11: ='6Consumo Especifico - OCULTA'!J11*'4Produção - OCULTA'!I10 -> 0 | ... N11: ='6Consumo Especifico - OCULTA'!N11*'4Produção - OCULTA'!M10 -> 0 | O11: =SUM(C11:N11) -> 0
A12: 12111080 | B12: Preparação 2 | C12: ='6Consumo Especifico - OCULTA'!C12*'4Produção - OCULTA'!B11 -> 13576559 | D12: ='6Consumo Especifico - OCULTA'!D12*'4Produção - OCULTA'!C11 -> 13248122 | E12: ='6Consumo Especifico - OCULTA'!E12*'4Produção - OCULTA'!D11 -> 13538725 | F12: ='6Consumo Especifico - OCULTA'!F12*'4Produção - OCULTA'!E11 -> 14781243 | G12: ='6Consumo Especifico - OCULTA'!G12*'4Produção - OCULTA'!F11 -> 15216844 | H12: ='6Consumo Especifico - OCULTA'!H12*'4Produção - OCULTA'!G11 -> 15312331 | I12: ='6Consumo Especifico - OCULTA'!I12*'4Produção - OCULTA'!H11 -> 15770686 | J12: ='6Consumo Especifico - OCULTA'!J12*'4Produção - OCULTA'!I11 -> 15004087 | ... N12: ='6Consumo Especifico - OCULTA'!N12*'4Produção - OCULTA'!M11 -> 14135045 | O12: =SUM(C12:N12) -> 1.7457338e+08
A13: 12133040 | B13: Usina 1 | C13: ='6Consumo Especifico - OCULTA'!C13*'4Produção - OCULTA'!B12 -> 0 | D13: ='6Consumo Especifico - OCULTA'!D13*'4Produção - OCULTA'!C12 -> 0 | E13: ='6Consumo Especifico - OCULTA'!E13*'4Produção - OCULTA'!D12 -> 0 | F13: ='6Consumo Especifico - OCULTA'!F13*'4Produção - OCULTA'!E12 -> 0 | G13: ='6Consumo Especifico - OCULTA'!G13*'4Produção - OCULTA'!F12 -> 0 | H13: ='6Consumo Especifico - OCULTA'!H13*'4Produção - OCULTA'!G12 -> 0 | I13: ='6Consumo Especifico - OCULTA'!I13*'4Produção - OCULTA'!H12 -> 0 | J13: ='6Consumo Especifico - OCULTA'!J13*'4Produção - OCULTA'!I12 -> 0 | ... N13: ='6Consumo Especifico - OCULTA'!N13*'4Produção - OCULTA'!M12 -> 0 | O13: =SUM(C13:N13) -> 0
A14: 12135040 | B14: Usina 2 | C14: ='6Consumo Especifico - OCULTA'!C14*'4Produção - OCULTA'!B13 -> 0 | D14: ='6Consumo Especifico - OCULTA'!D14*'4Produção - OCULTA'!C13 -> 0 | E14: ='6Consumo Especifico - OCULTA'!E14*'4Produção - OCULTA'!D13 -> 0 | F14: ='6Consumo Especifico - OCULTA'!F14*'4Produção - OCULTA'!E13 -> 0 | G14: ='6Consumo Especifico - OCULTA'!G14*'4Produção - OCULTA'!F13 -> 0 | H14: ='6Consumo Especifico - OCULTA'!H14*'4Produção - OCULTA'!G13 -> 0 | I14: ='6Consumo Especifico - OCULTA'!I14*'4Produção - OCULTA'!H13 -> 0 | J14: ='6Consumo Especifico - OCULTA'!J14*'4Produção - OCULTA'!I13 -> 0 | ... N14: ='6Consumo Especifico - OCULTA'!N14*'4Produção - OCULTA'!M13 -> 0 | O14: =SUM(C14:N14) -> 0
A15: 12136040 | B15: Usina 3 | C15: ='6Consumo Especifico - OCULTA'!C15*'4Produção - OCULTA'!B14 -> 14208007 | D15: ='6Consumo Especifico - OCULTA'!D15*'4Produção - OCULTA'!C14 -> 13696732 | E15: ='6Consumo Especifico - OCULTA'!E15*'4Produção - OCULTA'!D14 -> 11532297 | F15: ='6Consumo Especifico - OCULTA'!F15*'4Produção - OCULTA'!E14 -> 15634192 | G15: ='6Consumo Especifico - OCULTA'!G15*'4Produção - OCULTA'!F14 -> 15789968 | H15: ='6Consumo Especifico - OCULTA'!H15*'4Produção - OCULTA'!G14 -> 15947410 | I15: ='6Consumo Especifico - OCULTA'!I15*'4Produção - OCULTA'!H14 -> 16781463 | J15: ='6Consumo Especifico - OCULTA'!J15*'4Produção - OCULTA'!I14 -> 15792199 | ... N15: ='6Consumo Especifico - OCULTA'!N15*'4Produção - OCULTA'!M14 -> 14629501 | O15: =SUM(C15:N15) -> 1.7988224e+08
A16: 12138040 | B16: Usina 4 | C16: ='6Consumo Especifico - OCULTA'!C16*'4Produção - OCULTA'!B15 -> 19071584 | D16: ='6Consumo Especifico - OCULTA'!D16*'4Produção - OCULTA'!C15 -> 17736321 | E16: ='6Consumo Especifico - OCULTA'!E16*'4Produção - OCULTA'!D15 -> 21838381 | F16: ='6Consumo Especifico - OCULTA'!F16*'4Produção - OCULTA'!E15 -> 20961140 | G16: ='6Consumo Especifico - OCULTA'!G16*'4Produção - OCULTA'!F15 -> 20514207 | H16: ='6Consumo Especifico - OCULTA'!H16*'4Produção - OCULTA'!G15 -> 22132792 | I16: ='6Consumo Especifico - OCULTA'!I16*'4Produção - OCULTA'!H15 -> 22522503 | J16: ='6Consumo Especifico - OCULTA'!J16*'4Produção - OCULTA'!I15 -> 20471536 | ... N16: ='6Consumo Especifico - OCULTA'!N16*'4Produção - OCULTA'!M15 -> 20229319 | O16: =SUM(C16:N16) -> 2.469375e+08
A17: 12420080 | B17: Estocagem | C17: ='6Consumo Especifico - OCULTA'!C17*'4Produção - OCULTA'!B16 -> 927226.16 | D17: ='6Consumo Especifico - OCULTA'!D17*'4Produção - OCULTA'!C16 -> 876333.13 | E17: ='6Consumo Especifico - OCULTA'!E17*'4Produção - OCULTA'!D16 -> 924329.76 | F17: ='6Consumo Especifico - OCULTA'!F17*'4Produção - OCULTA'!E16 -> 1019629.6 | G17: ='6Consumo Especifico - OCULTA'!G17*'4Produção - OCULTA'!F16 -> 1012078.1 | H17: ='6Consumo Especifico - OCULTA'!H17*'4Produção - OCULTA'!G16 -> 1060358.6 | I17: ='6Consumo Especifico - OCULTA'!I17*'4Produção - OCULTA'!H16 -> 1095078.5 | J17: ='6Consumo Especifico - OCULTA'!J17*'4Produção - OCULTA'!I16 -> 1010990.4 | ... N17: ='6Consumo Especifico - OCULTA'!N17*'4Produção - OCULTA'!M16 -> 970720.24 | O17: =SUM(C17:N17) -> 11887243
B19: Consumo
A20: Área | B20: Unidade | C20: Jan | D20: Fev | E20: Mar | F20: Abr | G20: Mai | H20: Jun | I20: Jul | J20: Ago | K20: Set | L20: Out | M20: Nov | N20: Dez | O20: Planejado
A21: Filtragem Germano | B21: MWh | C21: =C3/1000 -> 3471.8614 | D21: =D3/1000 -> 3430.1499 | E21: =E3/1000 -> 3302.027 | F21: =F3/1000 -> 3371.8271 | G21: =G3/1000 -> 3326.5819 | H21: =H3/1000 -> 3337.4504 | I21: =I3/1000 -> 3354.3075 | J21: =J3/1000 -> 3377.1925 | ... O21: =O3/1000 -> 40705.808
A22: Mineração | B22: MWh | C22: =SUM(C4)/1000 -> 1870.8283 | D22: =SUM(D4)/1000 -> 1690.4599 | E22: =SUM(E4)/1000 -> 1871.5516 | F22: =SUM(F4)/1000 -> 1811.656 | G22: =SUM(G4)/1000 -> 1871.2928 | H22: =SUM(H4)/1000 -> 1810.7588 | I22: =SUM(I4)/1000 -> 1871.8404 | J22: =SUM(J4)/1000 -> 1871.6204 | ... O22: =SUM(O4)/1000 -> 22034.942
A23: Concentração | B23: MWh | C23: =SUM(C5:C7)/1000 -> 54364.489 | D23: =SUM(D5:D7)/1000 -> 54364.489 | E23: =SUM(E5:E7)/1000 -> 54364.489 | F23: =SUM(F5:F7)/1000 -> 54364.489 | G23: =SUM(G5:G7)/1000 -> 54364.489 | H23: =SUM(H5:H7)/1000 -> 54364.489 | I23: =SUM(I5:I7)/1000 -> 54364.489 | J23: =SUM(J5:J7)/1000 -> 54364.489 | ... O23: =SUM(O5:O7)/1000 -> 652373.87
A24: Mineroduto | B24: MWh | C24: =SUM(C8:C10)/1000 -> 9186.5758 | D24: =SUM(D8:D10)/1000 -> 9057.221 | E24: =SUM(E8:E10)/1000 -> 9731.7199 | F24: =SUM(F8:F10)/1000 -> 9976.3168 | G24: =SUM(G8:G10)/1000 -> 10182.119 | H24: =SUM(H8:H10)/1000 -> 10462.758 | I24: =SUM(I8:I10)/1000 -> 10660.862 | J24: =SUM(J8:J10)/1000 -> 10233.63 | ... O24: =SUM(O8:O10)/1000 -> 119004.79
A25: Preparação | B25: MWh | C25: =SUM(C11:C12)/1000 -> 13576.559 | D25: =SUM(D11:D12)/1000 -> 13248.122 | E25: =SUM(E11:E12)/1000 -> 13538.725 | F25: =SUM(F11:F12)/1000 -> 14781.243 | G25: =SUM(G11:G12)/1000 -> 15216.844 | H25: =SUM(H11:H12)/1000 -> 15312.331 | I25: =SUM(I11:I12)/1000 -> 15770.686 | J25: =SUM(J11:J12)/1000 -> 15004.087 | ... O25: =SUM(O11:O12)/1000 -> 174573.38
A26: Pelotização | B26: MWh | C26: =SUM(C13:C16)/1000 -> 33279.591 | D26: =SUM(D13:D16)/1000 -> 31433.054 | E26: =SUM(E13:E16)/1000 -> 33370.678 | F26: =SUM(F13:F16)/1000 -> 36595.333 | G26: =SUM(G13:G16)/1000 -> 36304.174 | H26: =SUM(H13:H16)/1000 -> 38080.202 | I26: =SUM(I13:I16)/1000 -> 39303.966 | J26: =SUM(J13:J16)/1000 -> 36263.735 | ... O26: =SUM(O13:O16)/1000 -> 426819.74
A27: Estocagem | B27: MWh | C27: =C17/1000 -> 927.22616 | D27: =D17/1000 -> 876.33313 | E27: =E17/1000 -> 924.32976 | F27: =F17/1000 -> 1019.6296 | G27: =G17/1000 -> 1012.0781 | H27: =H17/1000 -> 1060.3586 | I27: =I17/1000 -> 1095.0785 | J27: =J17/1000 -> 1010.9904 | ... N27: =N17/1000 -> 970.72024 | O27: =SUM(C27:N27) -> 11887.243
A28: Total | C28: =SUM(C21:C27) -> 116677.13 | D28: =SUM(D21:D27) -> 114099.83 | E28: =SUM(E21:E27) -> 117103.52 | F28: =SUM(F21:F27) -> 121920.49 | G28: =SUM(G21:G27) -> 122277.58 | H28: =SUM(H21:H27) -> 124428.35 | I28: =SUM(I21:I27) -> 126421.23 | J28: =SUM(J21:J27) -> 122125.74 | ... O28: =SUM(O21:O27) -> 1447399.8
A30: Totais por estado | B30: Unidade | C30: Jan | D30: Fev | E30: Mar | F30: Abr | G30: Mai | H30: Jun | I30: Jul | J30: Ago | K30: Set | L30: Out | M30: Nov | N30: Dez | O30: Planejado
A31: Minas Gerais | B31: MWh | C31: =SUM(C21:C24) -> 68893.755 | D31: =SUM(D21:D24) -> 68542.32 | E31: =SUM(E21:E24) -> 69269.788 | F31: =SUM(F21:F24) -> 69524.289 | G31: =SUM(G21:G24) -> 69744.483 | H31: =SUM(H21:H24) -> 69975.456 | I31: =SUM(I21:I24) -> 70251.499 | J31: =SUM(J21:J24) -> 69846.932 | ... O31: =SUM(O21:O24) -> 834119.41
A32: Espirito do Santo | B32: MWh | C32: =SUM(C25:C27) -> 47783.376 | D32: =SUM(D25:D27) -> 45557.509 | E32: =SUM(E25:E27) -> 47833.733 | F32: =SUM(F25:F27) -> 52396.206 | G32: =SUM(G25:G27) -> 52533.096 | H32: =SUM(H25:H27) -> 54452.892 | I32: =SUM(I25:I27) -> 56169.73 | J32: =SUM(J25:J27) -> 52278.812 | ... O32: =SUM(O25:O27) -> 613280.36
A33: Minas Gerais | B33: % | C33: =C31/C28 -> 0.59046494 | D33: =D31/D28 -> 0.60072237 | E33: =E31/E28 -> 0.59152609 | F33: =F31/F28 -> 0.57024284 | G33: =G31/G28 -> 0.57037834 | H33: =H31/H28 -> 0.56237551 | I33: =I31/I28 -> 0.55569385 | J33: =J31/J28 -> 0.57192636 | ... N33: =N31/N28 -> 0.58147804 | O33: =O31/$C$28 -> 7.1489537
A34: Espirito do Santo | B34: % | C34: =C32/C28 -> 0.40953506 | D34: =D32/D28 -> 0.39927763 | E34: =E32/E28 -> 0.40847391 | F34: =F32/F28 -> 0.42975716 | G34: =G32/G28 -> 0.42962166 | H34: =H32/H28 -> 0.43762449 | I34: =I32/I28 -> 0.44430615 | J34: =J32/J28 -> 0.42807364 | ... N34: =N32/N28 -> 0.41852196 | O34: =O32/$C$28 -> 5.2562174
A36: Divisão de Custo
A37: Centro de Custo | B37: Área | C37: Jan | D37: Fev | E37: Mar | F37: Abr | G37: Mai | H37: Jun | I37: Jul | J37: Ago | K37: Set | L37: Out | M37: Nov | N37: Dez | O37: Planejado
A38: 11140030 | B38: Filtragem Germano | C38: =(C3)/($C$31*1000) -> 0.050394429 | D38: =(D3)/(D31*1000) -> 0.050044263 | E38: =(E3)/(E31*1000) -> 0.04766908 | F38: =(F3)/(F31*1000) -> 0.048498548 | G38: =(G3)/(G31*1000) -> 0.047696703 | H38: =(H3)/(H31*1000) -> 0.047694586 | I38: =(I3)/(I31*1000) -> 0.047747131 | J38: =(J3)/(J31*1000) -> 0.048351337 | K38: =(K3)/(K31*1000) -> 0.047992079 | ... N38: =(N3)/(N31*1000) -> 0.050822812 | O38: =AVERAGE(C38:N38) -> 0.048806908
A39: =A11 -> 12110080 | B39: Mineração | C39: =(C4)/($C$31*1000) -> 0.027155267 | D39: =(D4)/($C$31*1000) -> 0.0245372 | E39: =(E4)/($C$31*1000) -> 0.027165766 | F39: =(F4)/($C$31*1000) -> 0.026296374 | G39: =(G4)/($C$31*1000) -> 0.02716201 | H39: =(H4)/($C$31*1000) -> 0.026283352 | I39: =(I4)/($C$31*1000) -> 0.027169958 | J39: =(J4)/($C$31*1000) -> 0.027166764 | ... N39: =(N4)/($C$31*1000) -> 0.027173327 | O39: =AVERAGE(C39:N39) -> 0.02665329
A40: =A12 -> 12111080 | B40: Beneficiamento 1 | C40: =(C5)/($C$31*1000) -> 0.015097387 | D40: =(D5)/($C$31*1000) -> 0.015097387 | E40: =(E5)/($C$31*1000) -> 0.015097387 | F40: =(F5)/($C$31*1000) -> 0.015097387 | G40: =(G5)/($C$31*1000) -> 0.015097387 | H40: =(H5)/($C$31*1000) -> 0.015097387 | I40: =(I5)/($C$31*1000) -> 0.015097387 | J40: =(J5)/($C$31*1000) -> 0.015097387 | ... N40: =(N5)/($C$31*1000) -> 0.015097387 | O40: =AVERAGE(C40:N40) -> 0.015097387
A41: =A13 -> 12133040 | B41: Beneficiamento 2 | C41: =(C6)/($C$31*1000) -> 0.36909209 | D41: =(D6)/($C$31*1000) -> 0.36909209 | E41: =(E6)/($C$31*1000) -> 0.36909209 | F41: =(F6)/($C$31*1000) -> 0.36909209 | G41: =(G6)/($C$31*1000) -> 0.36909209 | H41: =(H6)/($C$31*1000) -> 0.36909209 | I41: =(I6)/($C$31*1000) -> 0.36909209 | J41: =(J6)/($C$31*1000) -> 0.36909209 | ... N41: =(N6)/($C$31*1000) -> 0.36909209 | O41: =AVERAGE(C41:N41) -> 0.36909209
A42: =A14 -> 12135040 | B42: Beneficiamento 3 | C42: =(C7)/($C$31*1000) -> 0.40491672 | D42: =(D7)/($C$31*1000) -> 0.40491672 | E42: =(E7)/($C$31*1000) -> 0.40491672 | F42: =(F7)/($C$31*1000) -> 0.40491672 | G42: =(G7)/($C$31*1000) -> 0.40491672 | H42: =(H7)/($C$31*1000) -> 0.40491672 | I42: =(I7)/($C$31*1000) -> 0.40491672 | J42: =(J7)/($C$31*1000) -> 0.40491672 | ... N42: =(N7)/($C$31*1000) -> 0.40491672 | O42: =AVERAGE(C42:N42) -> 0.40491672
A43: =A16 -> 12138040 | B43: Mineroduto 1 | C43: =(C8)/($C$31*1000) -> 0.0033384739 | D43: =(D8)/($C$31*1000) -> 0.0030481718 | E43: =(E8)/($C$31*1000) -> 0.0033384739 | F43: =(F8)/($C$31*1000) -> 0.0032658983 | G43: =(G8)/($C$31*1000) -> 0.0030481718 | H43: =(H8)/($C$31*1000) -> 0.0033384739 | I43: =(I8)/($C$31*1000) -> 0.0032658983 | J43: =(J8)/($C$31*1000) -> 0.0033384739 | ... N43: =(N8)/($C$31*1000) -> 0.0033384739 | O43: =AVERAGE(C43:N43) -> 0.0032719463
...

Sheet 8Planejamento Geração - INPUT
A1: Geração (MWh) - Planejado | B1: Jan | C1: Fev | D1: Mar | E1: Abr | F1: Mai | G1: Jun | H1: Jul | I1: Ago | J1: Set | K1: Out | L1: Nov | M1: Dez
A2: Guilman Amorim | B2: 23979.167 | C2: 21368.452 | D2: 24144.728 | E2: 24559.148 | F2: 24972.533 | G2: 18891.653 | H2: 16420.194 | I2: 15320.572 | J2: 15407.459 | K2: 16528.92 | L2: 17382.712 | M2: 21189.34
A3: Muniz Freire | B3: 13943 | C3: 12192 | D3: 13483 | E3: 9537 | F3: 9350 | G3: 6545 | H3: 5891 | I3: 5830 | J3: 4930 | K3: 5800 | L3: 10753 | M3: 13750
A5: Os dados dessa planilha são todos imputados por cada área. Assim, alguém de área de produção deverá cadastrar todos os dados presentees nessa planilha.

Sheet 9Geração Própria - CALC
A1: Ano Base | B1: 2026
A2: Qtde de Horas Ponta/Dia | B2: 3
A3: Qtde de Horas no Dia | B3: 24
A5: Calendário | B5: Jan | C5: Fev | D5: Mar | E5: Abr | F5: Mai | G5: Jun | H5: Jul | I5: Ago | J5: Set | K5: Out | L5: Nov | M5: Dez
A6: Número de dias | B6: 31 | C6: 28 | D6: 31 | E6: 30 | F6: 31 | G6: 30 | H6: 31 | I6: 31 | J6: 30 | K6: 31 | L6: 30 | M6: 31
A7: Número de dias não uteis | B7: 10 | C7: 9 | D7: 10 | E7: 8 | F7: 11 | G7: 8 | H7: 8 | I7: 10 | J7: 8 | K7: 9 | L7: 10 | M7: 9
A8: Número de dias úteis no mês | B8: =B6-B7 -> 21 | C8: =C6-C7 -> 19 | D8: =D6-D7 -> 21 | E8: =E6-E7 -> 22 | F8: =F6-F7 -> 20 | G8: =G6-G7 -> 22 | H8: =H6-H7 -> 23 | I8: =I6-I7 -> 21 | ... M8: =M6-M7 -> 22
A9: Total de Horas/Ponta | B9: =B8*$B$2 -> 63 | C9: =C8*$B$2 -> 57 | D9: =D8*$B$2 -> 63 | E9: =E8*$B$2 -> 66 | F9: =F8*$B$2 -> 60 | G9: =G8*$B$2 -> 66 | H9: =H8*$B$2 -> 69 | I9: =I8*$B$2 -> 63 | ... M9: =M8*$B$2 -> 66
A10: Total de Horas/Fora Ponta | B10: =B11-B9 -> 681 | C10: =C11-C9 -> 615 | D10: =D11-D9 -> 681 | E10: =E11-E9 -> 654 | F10: =F11-F9 -> 684 | G10: =G11-G9 -> 654 | H10: =H11-H9 -> 675 | I10: =I11-I9 -> 681 | ... M10: =M11-M9 -> 678
A11: Total de Horas no mês | B11: =$B$3*B6 -> 744 | C11: =$B$3*C6 -> 672 | D11: =$B$3*D6 -> 744 | E11: =$B$3*E6 -> 720 | F11: =$B$3*F6 -> 744 | G11: =$B$3*G6 -> 720 | H11: =$B$3*H6 -> 744 | I11: =$B$3*I6 -> 744 | ... M11: =$B$3*M6 -> 744
